<?xml version="1.0"?>
<robot name="humanoid_robot" xmlns:xacro="http://www.ros.org/wiki/xacro">

  <!-- Include other xacro files -->
  <xacro:include filename="humanoid_constants.xacro"/>
  <xacro:include filename="humanoid_materials.xacro"/>

  <!-- Base Link -->
  <link name="base_link">
    <visual>
      <origin xyz="0 0 0" rpy="0 0 0"/>
      <geometry>
        <box size="0.3 0.2 0.15"/>
      </geometry>
      <material name="light_grey"/>
    </visual>
    <collision>
      <origin xyz="0 0 0" rpy="0 0 0"/>
      <geometry>
        <box size="0.3 0.2 0.15"/>
      </geometry>
    </collision>
    <inertial>
      <mass value="5.0"/>
      <origin xyz="0 0 0" rpy="0 0 0"/>
      <inertia ixx="0.1" ixy="0.0" ixz="0.0" iyy="0.1" iyz="0.0" izz="0.1"/>
    </inertial>
  </link>

  <!-- Head -->
  <joint name="head_joint" type="fixed">
    <parent link="base_link"/>
    <child link="head"/>
    <origin xyz="0.0 0.0 0.15" rpy="0 0 0"/>
  </joint>

  <link name="head">
    <visual>
      <origin xyz="0 0 0" rpy="0 0 0"/>
      <geometry>
        <sphere radius="0.08"/>
      </geometry>
      <material name="white"/>
    </visual>
    <collision>
      <origin xyz="0 0 0" rpy="0 0 0"/>
      <geometry>
        <sphere radius="0.08"/>
      </geometry>
    </collision>
    <inertial>
      <mass value="0.8"/>
      <origin xyz="0 0 0" rpy="0 0 0"/>
      <inertia ixx="0.002" ixy="0.0" ixz="0.0" iyy="0.002" iyz="0.0" izz="0.002"/>
    </inertial>
  </link>

  <!-- Left Arm -->
  <joint name="left_shoulder_joint" type="revolute">
    <parent link="base_link"/>
    <child link="left_upper_arm"/>
    <origin xyz="0.15 0.05 0.0" rpy="0 0 0"/>
    <axis xyz="0 1 0"/>
    <limit lower="-1.57" upper="1.57" effort="100" velocity="1.0"/>
  </joint>

  <link name="left_upper_arm">
    <visual>
      <origin xyz="0 0 -0.15" rpy="0 0 0"/>
      <geometry>
        <cylinder radius="0.04" length="0.3"/>
      </geometry>
      <material name="blue"/>
    </visual>
    <collision>
      <origin xyz="0 0 -0.15" rpy="0 0 0"/>
      <geometry>
        <cylinder radius="0.04" length="0.3"/>
      </geometry>
    </collision>
    <inertial>
      <mass value="0.5"/>
      <origin xyz="0 0 -0.15" rpy="0 0 0"/>
      <inertia ixx="0.005" ixy="0.0" ixz="0.0" iyy="0.005" iyz="0.0" izz="0.0005"/>
    </inertial>
  </link>

  <joint name="left_elbow_joint" type="revolute">
    <parent link="left_upper_arm"/>
    <child link="left_lower_arm"/>
    <origin xyz="0.0 0.0 -0.3" rpy="0 0 0"/>
    <axis xyz="0 1 0"/>
    <limit lower="-1.57" upper="1.57" effort="100" velocity="1.0"/>
  </joint>

  <link name="left_lower_arm">
    <visual>
      <origin xyz="0 0 -0.12" rpy="0 0 0"/>
      <geometry>
        <cylinder radius="0.03" length="0.24"/>
      </geometry>
      <material name="blue"/>
    </visual>
    <collision>
      <origin xyz="0 0 -0.12" rpy="0 0 0"/>
      <geometry>
        <cylinder radius="0.03" length="0.24"/>
      </geometry>
    </collision>
    <inertial>
      <mass value="0.3"/>
      <origin xyz="0 0 -0.12" rpy="0 0 0"/>
      <inertia ixx="0.002" ixy="0.0" ixz="0.0" iyy="0.002" iyz="0.0" izz="0.0002"/>
    </inertial>
  </link>

  <!-- Right Arm -->
  <joint name="right_shoulder_joint" type="revolute">
    <parent link="base_link"/>
    <child link="right_upper_arm"/>
    <origin xyz="0.15 -0.05 0.0" rpy="0 0 0"/>
    <axis xyz="0 1 0"/>
    <limit lower="-1.57" upper="1.57" effort="100" velocity="1.0"/>
  </joint>

  <link name="right_upper_arm">
    <visual>
      <origin xyz="0 0 -0.15" rpy="0 0 0"/>
      <geometry>
        <cylinder radius="0.04" length="0.3"/>
      </geometry>
      <material name="blue"/>
    </visual>
    <collision>
      <origin xyz="0 0 -0.15" rpy="0 0 0"/>
      <geometry>
        <cylinder radius="0.04" length="0.3"/>
      </geometry>
    </collision>
    <inertial>
      <mass value="0.5"/>
      <origin xyz="0 0 -0.15" rpy="0 0 0"/>
      <inertia ixx="0.005" ixy="0.0" ixz="0.0" iyy="0.005" iyz="0.0" izz="0.0005"/>
    </inertial>
  </link>

  <joint name="right_elbow_joint" type="revolute">
    <parent link="right_upper_arm"/>
    <child link="right_lower_arm"/>
    <origin xyz="0.0 0.0 -0.3" rpy="0 0 0"/>
    <axis xyz="0 1 0"/>
    <limit lower="-1.57" upper="1.57" effort="100" velocity="1.0"/>
  </joint>

  <link name="right_lower_arm">
    <visual>
      <origin xyz="0 0 -0.12" rpy="0 0 0"/>
      <geometry>
        <cylinder radius="0.03" length="0.24"/>
      </geometry>
      <material name="blue"/>
    </visual>
    <collision>
      <origin xyz="0 0 -0.12" rpy="0 0 0"/>
      <geometry>
        <cylinder radius="0.03" length="0.24"/>
      </geometry>
    </collision>
    <inertial>
      <mass value="0.3"/>
      <origin xyz="0 0 -0.12" rpy="0 0 0"/>
      <inertia ixx="0.002" ixy="0.0" ixz="0.0" iyy="0.002" iyz="0.0" izz="0.0002"/>
    </inertial>
  </link>

  <!-- Left Leg -->
  <joint name="left_hip_joint" type="revolute">
    <parent link="base_link"/>
    <child link="left_upper_leg"/>
    <origin xyz="-0.1 0.05 -0.075" rpy="0 0 0"/>
    <axis xyz="0 1 0"/>
    <limit lower="-1.57" upper="1.57" effort="100" velocity="1.0"/>
  </joint>

  <link name="left_upper_leg">
    <visual>
      <origin xyz="0 0 -0.2" rpy="0 0 0"/>
      <geometry>
        <cylinder radius="0.05" length="0.4"/>
      </geometry>
      <material name="red"/>
    </visual>
    <collision>
      <origin xyz="0 0 -0.2" rpy="0 0 0"/>
      <geometry>
        <cylinder radius="0.05" length="0.4"/>
      </geometry>
    </collision>
    <inertial>
      <mass value="1.0"/>
      <origin xyz="0 0 -0.2" rpy="0 0 0"/>
      <inertia ixx="0.015" ixy="0.0" ixz="0.0" iyy="0.015" iyz="0.0" izz="0.001"/>
    </inertial>
  </link>

  <joint name="left_knee_joint" type="revolute">
    <parent link="left_upper_leg"/>
    <child link="left_lower_leg"/>
    <origin xyz="0.0 0.0 -0.4" rpy="0 0 0"/>
    <axis xyz="0 1 0"/>
    <limit lower="-1.57" upper="1.57" effort="100" velocity="1.0"/>
  </joint>

  <link name="left_lower_leg">
    <visual>
      <origin xyz="0 0 -0.15" rpy="0 0 0"/>
      <geometry>
        <cylinder radius="0.04" length="0.3"/>
      </geometry>
      <material name="red"/>
    </visual>
    <collision>
      <origin xyz="0 0 -0.15" rpy="0 0 0"/>
      <geometry>
        <cylinder radius="0.04" length="0.3"/>
      </geometry>
    </collision>
    <inertial>
      <mass value="0.7"/>
      <origin xyz="0 0 -0.15" rpy="0 0 0"/>
      <inertia ixx="0.008" ixy="0.0" ixz="0.0" iyy="0.008" iyz="0.0" izz="0.0008"/>
    </inertial>
  </link>

  <joint name="left_foot_joint" type="fixed">
    <parent link="left_lower_leg"/>
    <child link="left_foot"/>
    <origin xyz="0.0 0.0 -0.3" rpy="0 0 0"/>
  </joint>

  <link name="left_foot">
    <visual>
      <origin xyz="0.05 0.0 -0.025" rpy="0 0 0"/>
      <geometry>
        <box size="0.15 0.1 0.05"/>
      </geometry>
      <material name="black"/>
    </visual>
    <collision>
      <origin xyz="0.05 0.0 -0.025" rpy="0 0 0"/>
      <geometry>
        <box size="0.15 0.1 0.05"/>
      </geometry>
    </collision>
    <inertial>
      <mass value="0.2"/>
      <origin xyz="0.05 0.0 -0.025" rpy="0 0 0"/>
      <inertia ixx="0.0002" ixy="0.0" ixz="0.0" iyy="0.0002" iyz="0.0" izz="0.0002"/>
    </inertial>
  </link>

  <!-- Right Leg -->
  <joint name="right_hip_joint" type="revolute">
    <parent link="base_link"/>
    <child link="right_upper_leg"/>
    <origin xyz="-0.1 -0.05 -0.075" rpy="0 0 0"/>
    <axis xyz="0 1 0"/>
    <limit lower="-1.57" upper="1.57" effort="100" velocity="1.0"/>
  </joint>

  <link name="right_upper_leg">
    <visual>
      <origin xyz="0 0 -0.2" rpy="0 0 0"/>
      <geometry>
        <cylinder radius="0.05" length="0.4"/>
      </geometry>
      <material name="red"/>
    </visual>
    <collision>
      <origin xyz="0 0 -0.2" rpy="0 0 0"/>
      <geometry>
        <cylinder radius="0.05" length="0.4"/>
      </geometry>
    </collision>
    <inertial>
      <mass value="1.0"/>
      <origin xyz="0 0 -0.2" rpy="0 0 0"/>
      <inertia ixx="0.015" ixy="0.0" ixz="0.0" iyy="0.015" iyz="0.0" izz="0.001"/>
    </inertial>
  </link>

  <joint name="right_knee_joint" type="revolute">
    <parent link="right_upper_leg"/>
    <child link="right_lower_leg"/>
    <origin xyz="0.0 0.0 -0.4" rpy="0 0 0"/>
    <axis xyz="0 1 0"/>
    <limit lower="-1.57" upper="1.57" effort="100" velocity="1.0"/>
  </joint>

  <link name="right_lower_leg">
    <visual>
      <origin xyz="0 0 -0.15" rpy="0 0 0"/>
      <geometry>
        <cylinder radius="0.04" length="0.3"/>
      </geometry>
      <material name="red"/>
    </visual>
    <collision>
      <origin xyz="0 0 -0.15" rpy="0 0 0"/>
      <geometry>
        <cylinder radius="0.04" length="0.3"/>
      </geometry>
    </collision>
    <inertial>
      <mass value="0.7"/>
      <origin xyz="0 0 -0.15" rpy="0 0 0"/>
      <inertia ixx="0.008" ixy="0.0" ixz="0.0" iyy="0.008" iyz="0.0" izz="0.0008"/>
    </inertial>
  </link>

  <joint name="right_foot_joint" type="fixed">
    <parent link="right_lower_leg"/>
    <child link="right_foot"/>
    <origin xyz="0.0 0.0 -0.3" rpy="0 0 0"/>
  </joint>

  <link name="right_foot">
    <visual>
      <origin xyz="0.05 0.0 -0.025" rpy="0 0 0"/>
      <geometry>
        <box size="0.15 0.1 0.05"/>
      </geometry>
      <material name="black"/>
    </visual>
    <collision>
      <origin xyz="0.05 0.0 -0.025" rpy="0 0 0"/>
      <geometry>
        <box size="0.15 0.1 0.05"/>
      </geometry>
    </collision>
    <inertial>
      <mass value="0.2"/>
      <origin xyz="0.05 0.0 -0.025" rpy="0 0 0"/>
      <inertia ixx="0.0002" ixy="0.0" ixz="0.0" iyy="0.0002" iyz="0.0" izz="0.0002"/>
    </inertial>
  </link>

  <!-- Sensors (IMU, Camera, etc.) -->
  <joint name="imu_joint" type="fixed">
    <parent link="base_link"/>
    <child link="imu_link"/>
    <origin xyz="0.05 0 0.05" rpy="0 0 0"/>
  </joint>

  <link name="imu_link">
    <inertial>
      <mass value="0.01"/>
      <origin xyz="0 0 0" rpy="0 0 0"/>
      <inertia ixx="0.0001" ixy="0" ixz="0" iyy="0.0001" iyz="0" izz="0.0001"/>
    </inertial>
  </link>

  <joint name="camera_joint" type="fixed">
    <parent link="head"/>
    <child link="camera_link"/>
    <origin xyz="0.05 0 0" rpy="0 0 0"/>
  </joint>

  <link name="camera_link">
    <inertial>
      <mass value="0.1"/>
      <origin xyz="0 0 0" rpy="0 0 0"/>
      <inertia ixx="0.001" ixy="0" ixz="0" iyy="0.001" iyz="0" izz="0.001"/>
    </inertial>
  </link>

</robot>